import subprocess
subprocess.call('python test_exception.py')
# subprocess.check_call('python test_exception.py')